Workbook

Sheet Tổng hợp
A1: STT | B1: Danh mục | C1: Trạng thái DNS lần 1 | D1: Trạng thái DNS lần 2 | E1: Trạng thái TPE lần 1 | F1: Trạng thái TPE lần 2 | G1: Tổng số testcase | H1: Số TH kiểm thử đạt | I1: Số TH kiểm thử không đạt | J1: Số TH đang xem xét (PE) | K1: Số TH kiểm chưa test | L1: Tổng số TH đã kiểm thử | M1: Tỉ lệ TH kiểm thử đạt (%P) | N1: Tỉ lệ TH kiểm thử không đạt (%F) | O1: Tỉ lệ TH đã thực hiện (%Cover) | P1: DNS note | Q1: TPE Note
A2: =Row()-ROW($A$1) | B2: DM dịch vụ sửa chữa và chi phí khác | C2: Đã xong | G2: ='1. DM dịch vụ sửa chữa và chi '!K16 | H2: ='1. DM dịch vụ sửa chữa và chi '!K11 | I2: ='1. DM dịch vụ sửa chữa và chi '!K12 | J2: ='1. DM dịch vụ sửa chữa và chi '!K13 | K2: ='1. DM dịch vụ sửa chữa và chi '!K14 | L2: ='1. DM dịch vụ sửa chữa và chi '!K15 | M2: =ROUND(H2/G2 * 100,2) | N2: =ROUND(I2/G2 * 100,2) | O2: =ROUND(L2/G2 * 100,2)
A3: =Row()-ROW($A$1) | B3: Danh mục tiền tệ | C3: Đã xong | G3: ='2. DM tiền tệ'!K16 | H3: ='2. DM tiền tệ'!K11 | I3: ='2. DM tiền tệ'!K12 | J3: ='2. DM tiền tệ'!K13 | K3: ='2. DM tiền tệ'!K14 | L3: ='2. DM tiền tệ'!K16 | M3: =ROUND(H3/G3 * 100,2) | N3: =ROUND(I3/G3 * 100,2) | O3: =ROUND(L3/G3 * 100,2)
A4: =Row()-ROW($A$1) | B4: Danh mục tài khoản | C4: Đã xong | G4: ='3. DM tài khoản'!K11 | H4: ='3. DM tài khoản'!K12 | I4: ='3. DM tài khoản'!K13 | J4: ='3. DM tài khoản'!K14 | K4: ='3. DM tài khoản'!K15 | L4: ='3. DM tài khoản'!K16 | M4: =ROUND(H4/G4 * 100,2) | N4: =ROUND(I4/G4 * 100,2) | O4: =ROUND(L4/G4 * 100,2)
A5: =Row()-ROW($A$1) | B5: Danh mục loại tài khoản | C5: Đã xong | G5: ='4. DM loại tài khoản'!K16 | H5: ='4. DM loại tài khoản'!K12 | I5: ='4. DM loại tài khoản'!K13 | J5: ='4. DM loại tài khoản'!K14 | K5: ='4. DM loại tài khoản'!K15 | L5: ='4. DM loại tài khoản'!K16 | M5: =ROUND(H5/G5 * 100,2) | N5: =ROUND(I5/G5 * 100,2) | O5: =ROUND(L5/G5 * 100,2)
A6: =Row()-ROW($A$1) | B6: Cập nhật nhanh giá dịch vụ | C6: Đã xong | G6: ='5. Cập nhật nhanh giá dịch vụ'!K16 | H6: ='5. Cập nhật nhanh giá dịch vụ'!K11 | I6: ='5. Cập nhật nhanh giá dịch vụ'!K12 | J6: ='5. Cập nhật nhanh giá dịch vụ'!K13 | K6: ='5. Cập nhật nhanh giá dịch vụ'!K14 | L6: ='5. Cập nhật nhanh giá dịch vụ'!K15 | M6: =ROUND(H6/G6 * 100,2) | N6: =ROUND(I6/G6 * 100,2) | O6: =ROUND(L6/G6 * 100,2)
A7: =Row()-ROW($A$1) | B7: DM serial thiết bị làm dịch vụ | C7: Đã xong | G7: ='6. DM serial thiết bị làm dịch '!K16 | H7: ='6. DM serial thiết bị làm dịch '!K11 | I7: ='6. DM serial thiết bị làm dịch '!K12 | J7: ='6. DM serial thiết bị làm dịch '!K13 | K7: ='6. DM serial thiết bị làm dịch '!K14 | L7: ='6. DM serial thiết bị làm dịch '!K15 | M7: =ROUND(H7/G7 * 100,2) | N7: =ROUND(I7/G7 * 100,2) | O7: =ROUND(L7/G7 * 100,2)
A8: =Row()-ROW($A$1) | B8: DM cấp dịch vụ bảo dưỡng | C8: Đã xong | G8: ='7. DM cấp dịch vụ bảo dưỡng'!K16 | H8: ='7. DM cấp dịch vụ bảo dưỡng'!K11 | I8: ='7. DM cấp dịch vụ bảo dưỡng'!K12 | J8: ='7. DM cấp dịch vụ bảo dưỡng'!K13 | K8: ='7. DM cấp dịch vụ bảo dưỡng'!K14 | L8: ='8. DM ghi chú kiểm tra bảo dưỡn'!K15 | M8: =ROUND(H8/G8 * 100,2) | N8: =ROUND(I8/G8 * 100,2) | O8: =ROUND(L8/G8 * 100,2)
A9: =Row()-ROW($A$1) | B9: DM ghi chú kiểm tra bảo dưỡng | C9: Đã xong | G9: ='8. DM ghi chú kiểm tra bảo dưỡn'!K16 | H9: ='8. DM ghi chú kiểm tra bảo dưỡn'!K11 | I9: ='8. DM ghi chú kiểm tra bảo dưỡn'!K12 | J9: ='8. DM ghi chú kiểm tra bảo dưỡn'!K13 | K9: ='8. DM ghi chú kiểm tra bảo dưỡn'!K14 | L9: ='8. DM ghi chú kiểm tra bảo dưỡn'!K15 | M9: =ROUND(H9/G9 * 100,2) | N9: =ROUND(I9/G9 * 100,2) | O9: =ROUND(L9/G9 * 100,2)
A10: =Row()-ROW($A$1) | B10: DM khách hàng | C10: Đang hoàn thiện | G10: ='9. DM khách hàng'!K16 | H10: ='9. DM khách hàng'!K11 | I10: ='9. DM khách hàng'!K12 | J10: ='9. DM khách hàng'!K13 | K10: ='9. DM khách hàng'!K14 | L10: ='9. DM khách hàng'!K15 | M10: =ROUND(H10/G10 * 100,2) | N10: =ROUND(I10/G10 * 100,2) | O10: =ROUND(L10/G10 * 100,2)
A11: =Row()-ROW($A$1) | B11: Danh mục ngân hàng | C11: Đã xong | G11: ='10. Danh mục ngân hàng'!K16 | H11: ='10. Danh mục ngân hàng'!K11 | I11: ='10. Danh mục ngân hàng'!K12 | J11: ='10. Danh mục ngân hàng'!K13 | K11: ='10. Danh mục ngân hàng'!K14 | L11: ='10. Danh mục ngân hàng'!K15 | M11: =ROUND(H11/G11 * 100,2) | N11: =ROUND(I11/G11 * 100,2) | O11: =ROUND(L11/G11 * 100,2)
A12: =Row()-ROW($A$1) | B12: Danh mục tài khoản ngân hàng | C12: Đã xong | G12: ='11. Danh mục tài khoản ngân hàn'!K16 | H12: ='11. Danh mục tài khoản ngân hàn'!K11 | I12: ='11. Danh mục tài khoản ngân hàn'!K12 | J12: ='11. Danh mục tài khoản ngân hàn'!K13 | K12: ='11. Danh mục tài khoản ngân hàn'!K14 | L12: ='11. Danh mục tài khoản ngân hàn'!K15 | M12: =ROUND(H12/G12 * 100,2) | N12: =ROUND(I12/G12 * 100,2) | O12: =ROUND(L12/G12 * 100,2)
A13: =Row()-ROW($A$1) | B13: Danh mục gói bảo dưỡng | C13: Đã xong | G13: ='12.Danh mục gói bảo dưỡng'!K16 | H13: ='12.Danh mục gói bảo dưỡng'!K11 | I13: ='12.Danh mục gói bảo dưỡng'!K12 | J13: ='12.Danh mục gói bảo dưỡng'!K13 | K13: ='12.Danh mục gói bảo dưỡng'!K14 | L13: ='12.Danh mục gói bảo dưỡng'!K15 | M13: =ROUND(H13/G13 * 100,2) | N13: =ROUND(I13/G13 * 100,2) | O13: =ROUND(L13/G13 * 100,2)
A14: =Row()-ROW($A$1) | B14: DM quốc gia | C14: Đã xong | G14: ='13. DM quốc gia'!K16 | H14: ='13. DM quốc gia'!K11 | I14: ='13. DM quốc gia'!K12 | J14: ='13. DM quốc gia'!K13 | K14: ='13. DM quốc gia'!K14 | L14: ='13. DM quốc gia'!K15 | M14: =ROUND(H14/G14 * 100,2) | N14: =ROUND(I14/G14 * 100,2) | O14: =ROUND(L14/G14 * 100,2)
A15: =Row()-ROW($A$1) | B15: DM khu vực | C15: Đã xong | G15: ='14. DM khu vực'!K16 | H15: ='14. DM khu vực'!K11 | I15: ='14. DM khu vực'!K12 | J15: ='14. DM khu vực'!K13 | K15: ='14. DM khu vực'!K14 | L15: ='14. DM khu vực'!K15 | M15: =ROUND(H15/G15 * 100,2) | N15: =ROUND(I15/G15 * 100,2) | O15: =ROUND(L15/G15 * 100,2)
A16: =Row()-ROW($A$1) | B16: DM phường/xã | C16: Đã xong | G16: ='15. DM phườngxã'!K16 | H16: ='15. DM phườngxã'!K11 | I16: ='15. DM phườngxã'!K12 | J16: ='15. DM phườngxã'!K13 | K16: ='15. DM phườngxã'!K14 | L16: ='15. DM phườngxã'!K15 | M16: =ROUND(H16/G16 * 100,2) | N16: =ROUND(I16/G16 * 100,2) | O16: =ROUND(L16/G16 * 100,2)
A17: =Row()-ROW($A$1) | B17: DM Tỉnh/TP | C17: Đã xong | G17: ='16. DM tỉnhTP'!K16 | H17: ='16. DM tỉnhTP'!K11 | I17: ='16. DM tỉnhTP'!K12 | J17: ='16. DM tỉnhTP'!K13 | K17: ='16. DM tỉnhTP'!K14 | L17: ='16. DM tỉnhTP'!K15 | M17: =ROUND(H17/G17 * 100,2) | N17: =ROUND(I17/G17 * 100,2) | O17: =ROUND(L17/G17 * 100,2)
A18: =Row()-ROW($A$1) | B18: DM đường/phố | C18: Đã xong | G18: ='17. DM đườngphố'!K16 | H18: ='17. DM đườngphố'!K11 | I18: ='17. DM đườngphố'!K12 | J18: ='17. DM đườngphố'!K13 | K18: ='17. DM đườngphố'!K14 | L18: ='17. DM đườngphố'!K15 | M18: =ROUND(H18/G18 * 100,2) | N18: =ROUND(I18/G18 * 100,2) | O18: =ROUND(L18/G18 * 100,2)
A19: =Row()-ROW($A$1) | B19: DM quận huyện | C19: Đã xong | G19: ='18. DM quận huyện'!K16 | H19: ='18. DM quận huyện'!K11 | I19: ='18. DM quận huyện'!K12 | J19: ='18. DM quận huyện'!K13 | K19: ='18. DM quận huyện'!K14 | L19: ='18. DM quận huyện'!K15 | M19: =ROUND(H19/G19 * 100,2) | N19: =ROUND(I19/G19 * 100,2) | O19: =ROUND(L19/G19 * 100,2)
A20: =Row()-ROW($A$1) | B20: DM vụ việc | C20: Đã xong | G20: ='19. DM vụ việc '!K16 | H20: ='19. DM vụ việc '!K11 | I20: ='19. DM vụ việc '!K12 | J20: ='19. DM vụ việc '!K13 | K20: ='19. DM vụ việc '!K14 | L20: ='21. DM mã phí'!K15 | M20: =ROUND(H20/G20 * 100,2) | N20: =ROUND(I20/G20 * 100,2) | O20: =ROUND(L20/G20 * 100,2)
A21: =Row()-ROW($A$1) | B21: DM nguồn vốn | C21: Đã xong | G21: ='20. DM nguồn vốn'!K16 | H21: ='20. DM nguồn vốn'!K11 | I21: ='20. DM nguồn vốn'!K12 | J21: ='20. DM nguồn vốn'!K13 | K21: ='20. DM nguồn vốn'!K14 | L21: ='20. DM nguồn vốn'!K15 | M21: =ROUND(H21/G21 * 100,2) | N21: =ROUND(I21/G21 * 100,2) | O21: =ROUND(L21/G21 * 100,2)
A22: 21 | B22: DM mã phí | C22: Đã xong | G22: ='21. DM mã phí'!K16 | H22: ='21. DM mã phí'!K11 | I22: ='21. DM mã phí'!K12 | J22: ='21. DM mã phí'!K13 | K22: ='21. DM mã phí'!K14 | L22: ='21. DM mã phí'!K15 | M22: =ROUND(H22/G22 * 100,2) | N22: =ROUND(I22/G22 * 100,2) | O22: =ROUND(L22/G22 * 100,2)
A23: 22 | B23: DM công việc, lỗi thiết bị | C23: Đã xong | G23: ='22. DM công việc, lỗi thiết bị'!K16 | H23: ='22. DM công việc, lỗi thiết bị'!K11 | I23: ='22. DM công việc, lỗi thiết bị'!K12 | J23: ='22. DM công việc, lỗi thiết bị'!K13 | K23: ='22. DM công việc, lỗi thiết bị'!K14 | L23: ='22. DM công việc, lỗi thiết bị'!K15 | M23: =ROUND(H23/G23 * 100,2) | N23: =ROUND(I23/G23 * 100,2) | O23: =ROUND(L23/G23 * 100,2)
A24: =Row()-ROW($A$1) | B24: Yêu cầu kiểm tra sửa chữa - bảo hành | C24: Đã xong | G24: ='25. YC kiểm tra sửa chữa - BH'!K16 | H24: ='25. YC kiểm tra sửa chữa - BH'!K11 | I24: ='25. YC kiểm tra sửa chữa - BH'!K12 | J24: ='25. YC kiểm tra sửa chữa - BH'!K13 | K24: ='25. YC kiểm tra sửa chữa - BH'!K14 | L24: ='25. YC kiểm tra sửa chữa - BH'!K15 | M24: =ROUND(H24/G24 * 100,2) | N24: =ROUND(I24/G24 * 100,2) | O24: =ROUND(L24/G24 * 100,2)
A25: =Row()-ROW($A$1) | B25: Phiếu xử lý yêu cầu | C25: Đã xong | G25: ='26. Phiếu xử lý yêu cầu'!K16 | H25: ='26. Phiếu xử lý yêu cầu'!K11 | I25: ='26. Phiếu xử lý yêu cầu'!K12 | J25: ='26. Phiếu xử lý yêu cầu'!K13 | K25: ='26. Phiếu xử lý yêu cầu'!K14 | L25: ='26. Phiếu xử lý yêu cầu'!K15 | M25: =ROUND(H25/G25 * 100,2) | N25: =ROUND(I25/G25 * 100,2) | O25: =ROUND(L25/G25 * 100,2)

Sheet 1. DM dịch vụ sửa  chữa và chi 
A1: MÔ TẢ TÍNH NĂNG (đọc trước khi xem testcase)
A2: 1. Mục đích tính năng | B2: Kiểm thử TOÀN BỘ màn hình “Danh mục dịch vụ sửa chữa và chi phí khác” của phân hệ CSKH (vào theo đường dẫn: CSKH → nhóm menu “Danh mục- Dịch vụ” → “Danh mục dịch vụ sửa chữa và chi phí khác”). ► Phạm vi kiểm thử: danh sách, tìm kiếm, bộ lọc, sắp xếp, phân trang, Tạo mới, Sửa, Xem, Khóa, Mở khóa, Xóa, Xuất Excel, phân quyền và toàn bộ ràng buộc nhập liệu. ► Danh mục này khai báo 3 thông số dùng cho nghiệp vụ phía sau: % Tính giá vốn, % VAT và ĐM giảm giá. Đây là nguồn dữ liệu cho Báo giá hãng và Hợp đồng hãng. ► Màn hình dùng CHUNG dữ liệu với màn danh mục chi phí tương ứng bên phần mềm ERP: sửa ở cổng nào thì cổng còn lại cũng thấy ngay.
A3: 2. Đối tượng được tính / hiển thị | B3: ► Danh sách hiển thị toàn bộ dịch vụ sửa chữa và chi phí khác đã khai báo. Dữ liệu thực tế trên cổng dev đang có 526 dòng. ► 2 trạng thái: “Hoạt động” (nhãn xanh) và “Khóa” (nhãn đỏ). ► 2 phân loại: “Có tính doanh thu” (nhãn xanh) và “Chi phí khác” (nhãn đỏ). Phân loại này do ô tích “Dịch vụ có tính doanh thu” trên form quyết định. ► Cột “ĐM giảm giá” hiển thị định mức giảm giá của CÔNG TY ĐANG CHỌN của người đăng nhập. Cùng một dịch vụ, người của công ty A và công ty B có thể thấy hai mức khác nhau — đây là hành vi đúng. Công ty chưa khai báo thì hiển thị “—”. ► 9 cột danh sách: STT | Tên dịch vụ / chi phí | Phân loại | ĐM giảm giá | % Tính giá vốn | % VAT | Trạng thái | Cập nhật | Hành động.
A4: 3. Đối tượng bị ẩn / không tính | B4: ► Các khoản “Chi phí phải trả” và “Chi phí bán hàng” KHÔNG thuộc màn này (vẫn quản lý bên phần mềm ERP), nên không xuất hiện trong danh sách. ► Nút Tạo mới / Sửa / Xóa / Khóa / Mở khóa CHỈ hiện với người có quyền quản lý danh mục. Người chỉ được xem thì chỉ thấy nút Xem và nút Xuất Excel. ► 2 dịch vụ hệ thống là “Chi phí đi lại” và “Chi phí vận chuyển” bị khóa cứng: không sửa, không xóa, không khóa, không mở khóa được. Nút vẫn hiển thị nhưng bị làm mờ. ► Dòng đang ở trạng thái Khóa: nút Sửa và nút Xóa bị làm mờ, phải Mở khóa trước. ► Cửa sổ Tạo mới KHÔNG có ô “Trạng thái” (dịch vụ mới luôn ở trạng thái Hoạt động); ô này chỉ xuất hiện ở cửa sổ Sửa. ► Nút “Lưu & Tiếp tục” chỉ có ở cửa sổ Tạo mới, không có ở cửa sổ Sửa và Xem.
A5: 4. Bộ lọc thời gian áp dụng cho | B5: ► Màn hình KHÔNG có bộ lọc theo khoảng thời gian. ► Cột “Cập nhật” chỉ để hiển thị: dòng trên là ngày giờ sửa gần nhất, dòng dưới là người sửa (dạng MÃ NV- Họ tên). Dịch vụ chưa từng được sửa thì hiển thị người tạo. ► Cột “Cập nhật” có sắp xếp được. ► Khi mới vào màn, danh sách sắp xếp theo ngày tạo giảm dần (dịch vụ mới nhất nằm đầu). ► Hệ thống ghi nhớ bộ lọc đang áp dụng trong 10 phút: rời màn rồi quay lại trong khoảng thời gian đó thì bộ lọc cũ còn nguyên; quá 10 phút thì bộ lọc tự trở về mặc định.
A6: 5. Cấu trúc dữ liệu / cây phân cấp | B6: ► Danh mục PHẲNG, không có cấu trúc cha- con, không gom nhóm. ► Mỗi dòng gồm: Tên dịch vụ / chi phí, Phân loại, % Tính giá vốn, % VAT, Trạng thái, và ĐM giảm giá. ► Riêng ĐM giảm giá được lưu TÁCH RIÊNG THEO TỪNG CÔNG TY: một dịch vụ có thể có nhiều mức giảm giá, mỗi công ty một mức. Người dùng chỉ nhìn thấy và chỉ sửa được mức của công ty mình đang chọn. ► Dịch vụ trong danh mục này được sử dụng ở 2 nơi: Báo giá hãng và Hợp đồng hãng. Đây là căn cứ để hệ thống quyết định một dịch vụ được xóa hẳn hay chỉ được chuyển sang Khóa.
A7: 6. Quy tắc cộng dồn / deduplicate | B7: ► KHÔNG cộng dồn — mỗi dòng là một dịch vụ độc lập, màn hình không có ô tổng. ► Chống trùng: Tên dịch vụ / chi phí phải là DUY NHẤT trong toàn danh mục, không phân biệt dịch vụ đó đang Hoạt động hay đang Khóa. Khi Sửa thì không tính chính dòng đang sửa là trùng. ► Mỗi công ty chỉ có DUY NHẤT một mức ĐM giảm giá cho một dịch vụ, lưu lại nhiều lần cũng không sinh dòng thừa. ► Bỏ trống hoặc nhập 0 ở ĐM giảm giá nghĩa là “không có định mức”: hệ thống gỡ mức giảm giá của CÔNG TY ĐANG CHỌN và KHÔNG đụng tới mức của các công ty khác. ► Xóa hẳn một dịch vụ thì mức giảm giá của MỌI công ty cũng bị xóa theo. Còn Khóa thì giữ nguyên toàn bộ mức giảm giá.
A8: 7. Phân quyền cấp | B8: • Quyền “Quản lý dịch vụ sửa chữa và chi phí khác” — xem danh sách, xem chi tiết, Tạo mới, Sửa, Xóa, Khóa, Mở khóa. • Quyền “Xem dịch vụ sửa chữa và chi phí khác” — CHỈ xem danh sách, xem chi tiết, tìm kiếm và Xuất Excel. • Mục menu “Danh mục dịch vụ sửa chữa và chi phí khác” chỉ hiện khi tài khoản có ít nhất một trong hai quyền trên. Không có quyền nào thì mục menu bị ẩn và vào thẳng đường dẫn cũng bị chặn. • Mọi thao tác làm thay đổi dữ liệu (Tạo mới, Sửa, Xóa, Khóa, Mở khóa) đều yêu cầu quyền “Quản lý dịch vụ sửa chữa và chi phí khác”. • Màn hình KHÔNG phân quyền theo cấp công ty / phòng ban / bộ phận: mọi người có quyền đều nhìn thấy đủ 526 dòng. Công ty đang chọn CHỈ ảnh hưởng tới giá trị cột “ĐM giảm giá”. Quyền được cấp theo vai trò (chức danh), không cấp trực tiếp cho từng nhân viên.
A9: 8. Cách tính các ô thống kê | B9: ► Màn hình KHÔNG có khối thống kê đầu trang. Chỉ có dòng đếm ở chân bảng: ► Ô “Hiển thị a–b / N dịch vụ / chi phí”: a và b là số thứ tự dòng đầu và dòng cuối của trang đang xem; N là TỔNG số dịch vụ khớp bộ lọc (không phải số dòng của trang). ► Các ô phần trăm trên bảng (% Tính giá vốn, % VAT, ĐM giảm giá) hiển thị đúng giá trị đã lưu, tối đa 2 chữ số thập phân, tự bỏ số 0 thừa (80,00 hiển thị thành “80%”). Không có giá trị thì hiển thị “—”. ► File Excel xuất ra luôn ghi phần trăm với đúng 2 chữ số thập phân (ví dụ 80,00) — khác cách rút gọn trên màn hình. Đây là hành vi đúng của hiện trạng, không phải lỗi.
A10: 9. Ghi chú đọc bảng | B10: ► Toàn bộ Tạo mới / Sửa / Xem đều mở trong một cửa sổ nhỏ ngay trên trang, không chuyển sang màn khác. ► Lỗi nhập liệu hiển thị ngay dưới từng ô (viền đỏ + chữ đỏ) kèm thông báo đỏ “Bạn chưa nhập đầy đủ thông tin” ở góc màn hình. Cửa sổ không bị đóng và dữ liệu đã nhập vẫn còn. ► Ở 3 ô phần trăm, DẤU PHẨY được hiểu là DẤU THẬP PHÂN: nhập “12,5” sẽ lưu là 12,5 phần trăm, KHÔNG phải 125. Đây là chủ đích, khác với màn Tiền tệ. ► “% Tính giá vốn” KHÔNG bị chặn trần 100 (chỉ cần từ 0 trở lên) — dữ liệu thật đang có dòng 321%. Riêng “% VAT” và “ĐM giảm giá” bị chặn tối đa 100. ► Nút Xóa không xóa ngay: hệ thống kiểm tra trước xem dịch vụ đã được dùng ở Báo giá hãng hay Hợp đồng hãng chưa. Nếu đã dùng, hộp thoại đổi thành “Xác nhận khóa” và dịch vụ chỉ bị chuyển sang trạng thái Khóa chứ không bị xóa. ► Phân trang mặc định 10 dòng/trang, chọn được 5 / 10 / 20 / 50. ► Các TH ghi “gọi thẳng chức năng, bỏ qua giao diện” là kiểm thử bảo mật, cần công cụ kiểm thử API (Postman hoặc tương đương) — dành cho tester kỹ thuật.
A11: Testcase _ Danh mục dịch vụ sửa chữa và chi phí khác- Cập nhật ngày 12/08/2026 | F11: TEST SUMMARY | I11: Số TH DNS kiểm thử đạt (P): | K11: =COUNTIF(K18:M1001,"Passed") | M11: Số trường hợp TP kiểm thử đạt (P): | P11: =COUNTIF(O18:Q200,"Passed")
I12: Số TH DNS kiểm thử không đạt (F) | K12: =COUNTIF(K18:M1001,"Failed") | M12: Số trường hợp TP kiểm thử không đạt (F) | P12: =COUNTIF(O19:Q201,"Fail")
I13: Số TH DNS kiểm thử đang xem xét (PE) | K13: =COUNTIF(K18:M1001,"Pending") | M13: Số trường hợp TP kiểm thử đang xem xét (PE) | P13: =COUNTIF(O20:Q202,"Pending")
I14: Số TH DNS kiểm thử chưa thực hiện | K14: =COUNTIF(K18:K1001,"Not Executed") | M14: Số trường hợp TP kiểm thử chưa thực hiện | P14: =K16-P15
I15: Tổng số TH DNS kiểm thử | K15: =COUNTIF(K18:K1001,"<>") | M15: Tổng số trường hợp TP kiểm thử | P15: =sum(P11:Q13)
I16: Tổng số testcase | K16: =COUNTIF(I18:I1001,"*")
A17: Module | B17: Nhóm chức năng | C17: TC ID | D17: Chức năng | E17: Priority | F17: Tiền điều kiện | G17: Bước thực hiện | H17: Test Data | I17: Expected Result (chi tiết) | J17: KQ thực tế | K17: DNS check lần 1 | L17: DNS check lần 2 | M17: DNS check lần 3 | N17: Ghi chú | O17: TP check lần 1 | P17: TP check lần 2 | Q17: TP check lần 3
C18: PHÂN QUYỀN VÀ TRUY CẬP
A19: DV sửa chữa & CP khác | B19: Phân quyền & truy cập | C19: TC-ROLE-00 | D19: Không có quyền nào của màn — menu và màn hình bị chặn | E19: P0 | F19: Tài khoản A đăng nhập được nhưng KHÔNG có quyền “Quản lý dịch vụ sửa chữa và chi phí khác” và cũng KHÔNG có quyền “Xem dịch vụ sửa chữa và chi phí khác” | G19: 1. Đăng nhập tài khoản A, vào phân hệ CSKH 2. Mở nhóm menu “Danh mục- Dịch vụ” hoặc theo đường link chứa /customer-care/costs | H19: Tài khoản A: không có quyền nào | I19: - Nhóm “Danh mục- Dịch vụ” KHÔNG có mục “Danh mục dịch vụ sửa chữa và chi phí khác” - Vào thẳng đường dẫn: hệ thống chặn, bảng không hiển thị dòng dữ liệu nào | J19: - Nhóm “Danh mục- Dịch vụ” KHÔNG có mục “Danh mục dịch vụ sửa chữa và chi phí khác” - Vào thẳng đường dẫn: hệ thống chặn, bảng không hiển thị dòng dữ liệu nào | K19: Passed
C20: TC-ROLE-01 | D20: Chỉ có quyền “Xem dịch vụ sửa chữa và chi phí khác” | E20: P0 | F20: Tài khoản B chỉ được cấp quyền “Xem dịch vụ sửa chữa và chi phí khác” | G20: 1. Đăng nhập B, vào màn hình 2. Quan sát thanh công cụ phía trên bảng 3. Quan sát cột Hành động và cột Trạng thái | H20: Tài khoản B: chỉ quyền xem | I20: - Vào được màn hình, bảng hiển thị đủ 526 dòng, bộ lọc dùng bình thường - Thanh công cụ CHỈ có nút “Xuất Excel”, KHÔNG có nút “Tạo mới” - Cột Hành động CHỈ có nút Xem; không có nút Sửa, không có nút Xóa - Cột Trạng thái chỉ có nhãn trạng thái, KHÔNG có nút ổ khóa | J20: - Vào được màn hình, bảng hiển thị đủ 526 dòng, bộ lọc dùng bình thường - Thanh công cụ CHỈ có nút “Xuất Excel”, KHÔNG có nút “Tạo mới” - Cột Hành động CHỈ có nút Xem; không có nút Sửa, không có nút Xóa - Cột Trạng thái chỉ có nhãn trạng thái, KHÔNG có nút ổ khóa | K20: Passed
C21: TC-ROLE-02 | D21: Có quyền “Quản lý dịch vụ sửa chữa và chi phí khác” | E21: P0 | F21: Tài khoản C được cấp quyền “Quản lý dịch vụ sửa chữa và chi phí khác” | G21: 1. Đăng nhập C, vào màn hình 2. Quan sát thanh công cụ, cột Hành động, cột Trạng thái | H21: Tài khoản C: quyền quản lý | I21: - Thanh công cụ có đủ nút “Tạo mới” và “Xuất Excel” - Cột Hành động có đủ 3 nút: Xem, Sửa, Xóa - Cột Trạng thái có nút ổ khóa để Khóa / Mở khóa | J21: - Thanh công cụ có đủ nút “Tạo mới” và “Xuất Excel” - Cột Hành động có đủ 3 nút: Xem, Sửa, Xóa - Cột Trạng thái có nút ổ khóa để Khóa / Mở khóa | K21: Passed
C22: TC-ROLE-03 | D22: Chỉ quyền Xem — bấm nút Xem vẫn mở được chi tiết | E22: P0 | F22: Tài khoản B (chỉ quyền xem); danh sách có ít nhất 1 dịch vụ | G22: 1. Đăng nhập B 2. Bấm nút Xem ở một dòng bất kỳ | H22: Dịch vụ “Dịch vụ đánh bóng xy lanh” | I22: - Cửa sổ “Xem dịch vụ / chi phí” mở ra bình thường - Mọi ô đều mờ, không nhập được; chân cửa sổ chỉ có nút “Đóng” | J22: - Cửa sổ “Xem dịch vụ / chi phí” mở ra bình thường - Mọi ô đều mờ, không nhập được; chân cửa sổ chỉ có nút “Đóng” | K22: Passed
C23: TC-ROLE-04 | D23: Chỉ quyền Xem — gọi thẳng chức năng Tạo mới, bỏ qua giao diện | E23: P0 | F23: Tài khoản B (chỉ quyền xem), đã đăng nhập hợp lệ | G23: 1. Dùng công cụ kiểm thử API gọi thẳng chức năng Tạo mới với dữ liệu hợp lệ 2. Vào lại danh sách kiểm tra | H23: Tên = “TC bypass”, % Tính giá vốn = 10, % VAT = 8 | I23: - Hệ thống từ chối, báo không có quyền - KHÔNG có dịch vụ mới nào được tạo ra | J23: - Hệ thống từ chối, báo không có quyền - KHÔNG có dịch vụ mới nào được tạo ra | K23: Passed
C24: TC-ROLE-05 | D24: Chỉ quyền Xem — gọi thẳng chức năng Sửa, bỏ qua giao diện | E24: P0 | F24: Tài khoản B (chỉ quyền xem); tồn tại dịch vụ X đang Hoạt động | G24: 1. Dùng công cụ kiểm thử API gọi thẳng chức năng Sửa dịch vụ X 2. Mở lại dịch vụ X trên màn hình để đối chiếu | H24: Tài khoản B, dịch vụ X | I24: - Hệ thống từ chối, báo không có quyền - Dịch vụ X giữ nguyên mọi thông tin, cột “Cập nhật” không đổi | J24: - Hệ thống từ chối, báo không có quyền - Dịch vụ X giữ nguyên mọi thông tin, cột “Cập nhật” không đổi | K24: Passed
C25: TC-ROLE-06 | D25: Chỉ quyền Xem — gọi thẳng chức năng Xóa / Khóa / Mở khóa | E25: P0 | F25: Tài khoản B (chỉ quyền xem); dịch vụ X đang Hoạt động | G25: 1. Dùng công cụ kiểm thử API gọi lần lượt 3 chức năng: Xóa, Khóa, Mở khóa cho dịch vụ X | H25: 3 lần gọi, cùng tài khoản B | I25: - CẢ 3 lần đều bị hệ thống từ chối, báo không có quyền - Dịch vụ X vẫn còn và vẫn ở trạng thái Hoạt động | J25: - CẢ 3 lần đều bị hệ thống từ chối, báo không có quyền - Dịch vụ X vẫn còn và vẫn ở trạng thái Hoạt động | K25: Passed
C26: TC-ROLE-07 | D26: Không có quyền nào — gọi thẳng chức năng xem danh sách và xem chi tiết | E26: P0 | F26: Tài khoản A (không có quyền nào của màn), đã đăng nhập hợp lệ | G26: 1. Dùng công cụ kiểm thử API gọi chức năng lấy danh sách 2. Gọi chức năng xem chi tiết một dịch vụ | H26: Tài khoản A | I26: - Cả 2 lần đều bị từ chối, báo không có quyền - Kết quả trả về KHÔNG để lộ bất kỳ thông tin nào của danh mục | J26: - Cả 2 lần đều bị từ chối, báo không có quyền - Kết quả trả về KHÔNG để lộ bất kỳ thông tin nào của danh mục | K26: Passed
C27: TC-ROLE-08 | D27: ĐM giảm giá hiển thị theo công ty đang chọn của người đăng nhập | E27: P0 | F27: Dịch vụ “Dịch vụ đánh bóng xy lanh” đã khai báo ĐM giảm giá: công ty 1 là 5%, công ty 4 là 12%. Tài khoản C thuộc công ty 1, tài khoản D thuộc công ty 4, cả hai đều có quyền quản lý | G27: 1. Đăng nhập C, xem cột “ĐM giảm giá” của dòng đó 2. Đăng nhập D, xem lại đúng dòng đó | H27: C ở công ty 1; D ở công ty 4 | I27: - Tài khoản C thấy “5%” - Tài khoản D thấy “12%” - Cùng một dịch vụ nhưng 2 người thấy 2 giá trị khác nhau — đây là hành vi đúng, không phải lỗi | J27: - Tài khoản C thấy “5%” - Tài khoản D thấy “12%” - Cùng một dịch vụ nhưng 2 người thấy 2 giá trị khác nhau — đây là hành vi đúng, không phải lỗi | K27: Passed
C28: TC-ROLE-09 | D28: Công ty chưa khai báo ĐM giảm giá — hiển thị gạch ngang | E28: P1 | F28: Dịch vụ “Hướng dẫn, bàn giao máy hàn rút tồn” chưa được khai báo ĐM giảm giá cho công ty của người đăng nhập | G28: 1. Đăng nhập, xem cột “ĐM giảm giá” của dòng đó | H28: Chưa khai báo định mức | I28: - Cột “ĐM giảm giá” hiển thị “—” - KHÔNG hiển thị 0% và không để trống | J28: - Cột “ĐM giảm giá” hiển thị “—” - KHÔNG hiển thị 0% và không để trống | K28: Passed
C29: I. HIỂN THỊ TRANG & TRUY CẬP
A30: DV sửa chữa & CP khác | B30: HIỂN THỊ TRANG & TRUY CẬP | C30: TC_01.001 | D30: Truy cập màn hình từ menu | E30: P0 | F30: Tài khoản C có quyền quản lý danh mục | G30: 1. Vào phân hệ CSKH 2. Bấm nhóm menu “Danh mục- Dịch vụ” 3. Bấm “Danh mục dịch vụ sửa chữa và chi phí khác” | H30: Tài khoản C | I30: - Mở đúng màn hình danh mục - Tiêu đề trên thanh trên cùng ghi “Danh mục dịch vụ sửa chữa và chi phí khác” | J30: - Mở đúng màn hình danh mục - Tiêu đề trên thanh trên cùng ghi “Danh mục dịch vụ sửa chữa và chi phí khác” | K30: Passed
C31: TC_01.002 | D31: Bố cục trang khi vào lần đầu | E31: P0 | F31: Tài khoản C vào màn hình lần đầu trong ngày (chưa từng đặt bộ lọc) | G31: 1. Vào màn hình 2. Quan sát bố cục | H31: — | I31: - Trang có 2 khối: panel “Bộ lọc dịch vụ sửa chữa và chi phí khác” ở trên và bảng danh sách ở dưới - Bộ lọc nâng cao đang THU GỌN, chỉ hiện ô tìm nhanh cùng 2 nút “Tìm kiếm” và “Làm mới” - KHÔNG có khối thống kê ở đầu trang | J31: - Trang có 2 khối: panel “Bộ lọc dịch vụ sửa chữa và chi phí khác” ở trên và bảng danh sách ở dưới - Bộ lọc nâng cao đang THU GỌN, chỉ hiện ô tìm nhanh cùng 2 nút “Tìm kiếm” và “Làm mới” - KHÔNG có khối thống kê ở đầu trang | K31: Passed
C32: TC_01.003 | D32: Hiển thị đủ và đúng thứ tự các cột | E32: P0 | F32: Danh sách có ít nhất 1 dịch vụ | G32: 1. Vào danh sách 2. Đọc tiêu đề từng cột từ trái sang phải | H32: — | I32: - Đúng 9 cột theo thứ tự: STT | Tên dịch vụ / chi phí | Phân loại | ĐM giảm giá | % Tính giá vốn | % VAT | Trạng thái | Cập nhật | Hành động - Cột STT và cột Tên đứng yên (dính bên trái) khi cuộn ngang | J32: - Đúng 9 cột theo thứ tự: STT | Tên dịch vụ / chi phí | Phân loại | ĐM giảm giá | % Tính giá vốn | % VAT | Trạng thái | Cập nhật | Hành động - Cột STT và cột Tên đứng yên (dính bên trái) khi cuộn ngang | K32: Passed
C33: TC_01.004 | D33: Biểu tượng sắp xếp chỉ có ở đúng 6 cột | E33: P1 | F33: Đang ở màn danh sách | G33: 1. Quan sát biểu tượng 2 mũi tên trên từng tiêu đề cột | H33: — | I33: - CÓ biểu tượng sắp xếp ở: Tên dịch vụ / chi phí, ĐM giảm giá, % Tính giá vốn, % VAT, Trạng thái, Cập nhật - KHÔNG có ở: STT, Phân loại, Hành động | J33: - CÓ biểu tượng sắp xếp ở: Tên dịch vụ / chi phí, ĐM giảm giá, % Tính giá vốn, % VAT, Trạng thái, Cập nhật - KHÔNG có ở: STT, Phân loại, Hành động | K33: Passed
C34: TC_01.005 | D34: Nhãn Trạng thái Hoạt động / Khóa | E34: P0 | F34: Danh sách có dịch vụ đang Hoạt động và dịch vụ đang Khóa (ví dụ “test01111” đang Khóa) | G34: 1. Quan sát cột Trạng thái của 2 dòng đó | H34: 1 dòng Hoạt động, 1 dòng Khóa | I34: - Dòng Hoạt động: nhãn xanh “Hoạt động” kèm biểu tượng dấu tích - Dòng Khóa: nhãn đỏ “Khóa” kèm biểu tượng ổ khóa | J34: - Dòng Hoạt động: nhãn xanh “Hoạt động” kèm biểu tượng dấu tích - Dòng Khóa: nhãn đỏ “Khóa” kèm biểu tượng ổ khóa | K34: Passed
C35: TC_01.006 | D35: Nhãn Phân loại | E35: P0 | F35: Danh sách có cả dịch vụ có tính doanh thu và khoản chi phí khác | G35: 1. Quan sát cột Phân loại | H35: “Trang test” có tính doanh thu; “test01111” là chi phí khác | I35: - Dịch vụ có tính doanh thu: nhãn xanh “Có tính doanh thu” kèm biểu tượng biểu đồ - Chi phí khác: nhãn đỏ “Chi phí khác” kèm biểu tượng nhãn giá | J35: - Dịch vụ có tính doanh thu: nhãn xanh “Có tính doanh thu” kèm biểu tượng biểu đồ - Chi phí khác: nhãn đỏ “Chi phí khác” kèm biểu tượng nhãn giá | K35: Passed
C36: TC_01.007 | D36: Cột Cập nhật hiển thị thời điểm và người sửa | E36: P1 | F36: Dịch vụ X được nhân viên “10410008- Cao Đình Hòe” sửa lần cuối lúc 16/07/2026 15:12 | G36: 1. Quan sát cột Cập nhật của dòng X | H36: Sửa lần cuối 16/07/2026 15:12 bởi Cao Đình Hòe | I36: - Dòng trên: “16/07/2026 15:12” - Dòng dưới: “bởi 10410008- Cao Đình Hòe” (tên in đậm) | J36: - Dòng trên: “16/07/2026 15:12” - Dòng dưới: “bởi 10410008- Cao Đình Hòe” (tên in đậm) | K36: Passed
C37: TC_01.008 | D37: Dịch vụ chưa từng sửa — cột Cập nhật lấy người tạo | E37: P1 | F37: Dịch vụ Y do “DNS01- DNS Admin” tạo và CHƯA từng được sửa lần nào | G37: 1. Quan sát cột Cập nhật của dòng Y | H37: Chưa từng sửa | I37: - Vẫn hiển thị “bởi DNS01- DNS Admin” (lấy theo người tạo), không được để trống | J37: - Vẫn hiển thị “bởi DNS01- DNS Admin” (lấy theo người tạo), không được để trống | K37: Passed
C38: TC_01.009 | D38: Định dạng phần trăm — tự bỏ số 0 thừa | E38: P1 | F38: Dịch vụ có % Tính giá vốn là 80,00 và % VAT là 8,00 | G38: 1. Quan sát cột “% Tính giá vốn” và “% VAT” | H38: 80,00 và 8,00 | I38: - Hiển thị “80%” và “8%”, KHÔNG hiển thị “80,00%” | J38: - Hiển thị “80%” và “8%”, KHÔNG hiển thị “80,00%” | K38: Passed
C39: TC_01.010 | D39: Giá trị trống hiển thị gạch ngang | E39: P1 | F39: Dịch vụ chưa khai báo ĐM giảm giá | G39: 1. Quan sát cột “ĐM giảm giá” | H39: Chưa khai báo | I39: - Hiển thị “—”, không hiển thị 0% và không để trống | J39: - Hiển thị “—”, không hiển thị 0% và không để trống | K39: Passed
C40: TC_01.011 | D40: Danh sách rỗng khi bộ lọc không khớp | E40: P1 | F40: Danh sách đang có dữ liệu | G40: 1. Nhập “ZZZZZ999” vào ô tìm nhanh 2. Bấm “Tìm kiếm” | H40: Từ khóa: ZZZZZ999 | I40: - Bảng hiển thị dòng chữ “Không có dữ liệu phù hợp bộ lọc.” - Không báo lỗi, không treo trang | J40: - Bảng hiển thị dòng chữ “Không có dữ liệu phù hợp bộ lọc.” - Không báo lỗi, không treo trang | K40: Passed
...

Sheet 2. DM tiền tệ
A1: MÔ TẢ TÍNH NĂNG (đọc trước khi xem testcase)
A2: 1. Mục đích tính năng | B2: Quản lý tập trung danh sách các loại tiền tệ và tỷ giá quy đổi ra Đồng Việt Nam, dùng chung cho toàn hệ thống (báo giá, hợp đồng, đề nghị thu tiền, đề nghị chi tiền, công nợ, phiếu kế toán…). Màn hình nằm ở phân hệ Tài chính → nhóm menu Danh mục → Danh mục tiền tệ. Đây là màn được chuyển từ hệ thống cũ sang. Hai cổng dùng CHUNG một danh sách tiền tệ, nên sửa ở cổng mới thì cổng cũ cũng thấy ngay và ngược lại.
A3: 2. Đối tượng được tính / hiển thị | B3: - Toàn bộ tiền tệ trong danh mục, KHÔNG phân theo công ty / phòng ban — ai có quyền vào màn thì thấy đủ như nhau. - Hiển thị cả tiền tệ ở trạng thái Hoạt động và trạng thái Khóa (mặc định không lọc trạng thái). - Mỗi dòng gồm 7 cột: STT, Mã tiền tệ, Tên tiền tệ (kèm dòng phụ "Tên gọi khác" nếu có), Tỷ giá (VNĐ), Cập nhật, Trạng thái, Hành động. - Cột Tên tiền tệ chỉ hiện dòng phụ "Tên gọi khác" khi tiền tệ đó có nhập tên gọi khác; không nhập thì không hiện dòng phụ (không hiện dòng trống).
A4: 3. Đối tượng bị ẩn / không tính | B4: - Không có tiền tệ nào bị ẩn khỏi danh sách: màn này không có khái niệm xóa mềm / lưu trữ. - Tiền tệ ở trạng thái Khóa VẪN hiện trong danh sách của màn này, chỉ bị chặn không cho chọn mới ở các màn nghiệp vụ khác. - Khi lọc theo Trạng thái = Hoạt động thì các tiền tệ đang Khóa bị loại khỏi kết quả và ngược lại.
A5: 4. Bộ lọc thời gian áp dụng cho | B5: Không áp dụng. Màn hình không có bộ lọc theo khoảng thời gian. Cột Cập nhật chỉ để xem và để sắp xếp, không phải điều kiện lọc.
A6: 5. Cấu trúc dữ liệu / cây phân cấp | B6: Danh sách phẳng, không phân cấp cha- con. Mã tiền tệ là giá trị không được trùng trong toàn danh mục. Tỷ giá luôn được hiểu là: 1 đơn vị tiền tệ đó bằng bao nhiêu Đồng Việt Nam.
A7: 6. Quy tắc cộng dồn / deduplicate | B7: Không cộng dồn. Mỗi tiền tệ là một dòng độc lập. Quy tắc chống trùng: Mã tiền tệ là duy nhất. Thêm mới hoặc sửa sang một mã đã có sẽ bị chặn với thông báo "Mã tiền tệ đã tồn tại" ngay dưới ô Mã tiền tệ. Tên tiền tệ và Tên gọi khác KHÔNG bắt buộc duy nhất — được phép trùng.
A8: 7. Phân quyền cấp | B8: Hai quyền dành riêng cho màn này: - "Xem danh mục tiền tệ": vào được màn hình, xem danh sách, mở xem chi tiết, xuất Excel. - "Quản lý danh mục tiền tệ": thêm mới, sửa, khóa, mở khóa, xóa. Người có quyền này cũng vào và xem được màn hình. Không có quyền nào trong hai quyền trên thì không vào được màn hình. Danh mục KHÔNG phân quyền theo công ty / phòng ban / bộ phận.
A9: 8. Cách tính các ô thống kê | B9: - Dòng "Hiển thị a- b / N" dưới bảng: a là số thứ tự dòng đầu của trang đang xem, b là dòng cuối, N là tổng số tiền tệ khớp bộ lọc hiện tại (không phải tổng toàn danh mục). - Cột STT được đánh theo trang: trang 2 với cỡ trang 10 thì bắt đầu từ 11. - Cột Tỷ giá (VNĐ) hiển thị theo định dạng Việt Nam: dấu chấm ngăn cách hàng nghìn, dấu phẩy ngăn phần thập phân, luôn 2 chữ số thập phân. Ví dụ 26.520,00.
A10: 9. Ghi chú đọc bảng | B10: - Ô nhập Tỷ giá dùng dấu phẩy làm dấu thập phân theo chuẩn Việt Nam; tối đa 999.999,99. Nhập vượt trần sẽ bị chặn kèm thông báo. - Tỷ giá được hệ thống TỰ ĐỘNG cập nhật lại hằng ngày lúc 03:00 sáng theo tỷ giá bán của Vietcombank, khớp theo Mã tiền tệ (riêng VNĐ được bỏ qua). Vì vậy tỷ giá sửa tay hôm nay có thể khác vào sáng hôm sau — đây là hành vi đúng, không phải lỗi. Khi kiểm thử tỷ giá, hãy đối chiếu trong cùng một ngày. - Nút Xóa bị mờ (không bấm được) với tiền tệ đang được dùng ở chứng từ khác. Trạng thái mờ này xuất hiện chậm hơn bảng khoảng vài trăm mili giây — vừa mở màn mà nút còn sáng là bình thường, bấm vào vẫn bị hệ thống chặn lại. - Nút Khóa / Mở khóa nằm NGAY TRONG cột Trạng thái, không nằm ở cột Hành động. - Bộ lọc được hệ thống ghi nhớ trong 10 phút: rời màn rồi quay lại trong 10 phút thì bộ lọc cũ vẫn còn. Khi kiểm thử bộ lọc, nhớ bấm Làm mới trước mỗi kịch bản. - Nút Xuất Excel luôn hiện với mọi người vào được màn.
A11: Testcase _ Danh mục tiền tệ- Cập nhật ngày 13/08/2026 | F11: TEST SUMMARY | I11: Số TH DNS kiểm thử đạt (P): | K11: =COUNTIF(K18:M1001,"Passed") | M11: Số trường hợp TP kiểm thử đạt (P): | P11: =COUNTIF(O18:Q200,"Passed")
I12: Số TH DNS kiểm thử không đạt (F) | K12: =COUNTIF(K18:M1001,"Failed") | M12: Số trường hợp TP kiểm thử không đạt (F) | P12: =COUNTIF(O19:Q201,"Fail")
I13: Số TH DNS kiểm thử đang xem xét (PE) | K13: =COUNTIF(K18:M1001,"Pending") | M13: Số trường hợp TP kiểm thử đang xem xét (PE) | P13: =COUNTIF(O20:Q202,"Pending")
I14: Số TH DNS kiểm thử chưa thực hiện | K14: =COUNTIF(K18:K1001,"Not Executed") | M14: Số trường hợp TP kiểm thử chưa thực hiện | P14: =K16-P15
I15: Tổng số TH DNS kiểm thử | K15: =COUNTIF(K18:K1001,"<>") | M15: Tổng số trường hợp TP kiểm thử | P15: =sum(P11:Q13)
I16: Tổng số testcase | K16: =COUNTIF(I18:I1003,"*")
A17: Module | B17: Nhóm chức năng | C17: TC ID | D17: Chức năng | E17: Priority | F17: Tiền điều kiện | G17: Bước thực hiện | H17: Test Data | I17: Expected Result (chi tiết) | J17: KQ thực tế | K17: DNS check lần 1 | L17: DNS check lần 2 | M17: DNS check lần 3 | N17: Ghi chú | O17: TP check lần 1 | P17: TP check lần 2 | Q17: TP check lần 3
C18: Phân quyền & truy cập
A19: Danh mục tiền tệ | B19: Phân quyền & truy cập | C19: TC-ROLE-01 | D19: Vào màn hình khi chỉ có quyền Xem | E19: P0 | F19: Có sẵn 2 tài khoản: tài khoản A chỉ được cấp quyền "Xem danh mục tiền tệ"; tài khoản B được cấp quyền "Quản lý danh mục tiền tệ". Danh mục đang có 11 tiền tệ, trong đó VNĐ và USD đang được dùng ở chứng từ khác, tiền tệ "TST" mới tạo chưa dùng ở đâu. | G19: 1. Đăng nhập bằng tài khoản A 2. Vào phân hệ Tài chính → Danh mục → Danh mục tiền tệ hoặc theo đường dẫn chứa /finance/currencies | H19: Tài khoản A (chỉ có quyền Xem danh mục tiền tệ) | I19: - Vào được màn hình, bảng hiển thị đủ 11 tiền tệ - KHÔNG có nút Tạo mới - Trên mỗi dòng chỉ có nút Xem (hình con mắt); KHÔNG có nút Sửa, nút Xóa - Trong cột Trạng thái KHÔNG có nút Khóa / Mở khóa - Vẫn có nút Xuất Excel | J19: - Vào được màn hình, bảng hiển thị đủ 11 tiền tệ - KHÔNG có nút Tạo mới - Trên mỗi dòng chỉ có nút Xem (hình con mắt); KHÔNG có nút Sửa, nút Xóa - Trong cột Trạng thái KHÔNG có nút Khóa / Mở khóa - Vẫn có nút Xuất Excel | K19: Passed
C20: TC-ROLE-02 | D20: Vào màn hình khi có quyền Quản lý | E20: P0 | F20: Có sẵn 2 tài khoản: tài khoản A chỉ được cấp quyền "Xem danh mục tiền tệ"; tài khoản B được cấp quyền "Quản lý danh mục tiền tệ". Danh mục đang có 11 tiền tệ, trong đó VNĐ và USD đang được dùng ở chứng từ khác, tiền tệ "TST" mới tạo chưa dùng ở đâu. | G20: 1. Đăng nhập bằng tài khoản B 2. Vào Danh mục tiền tệ | H20: Tài khoản B (có quyền Quản lý danh mục tiền tệ) | I20: - Vào được màn hình - Có nút Tạo mới và nút Xuất Excel - Mỗi dòng có đủ 3 nút: Xem, Sửa, Xóa - Cột Trạng thái có nút Khóa (với dòng đang Hoạt động) hoặc Mở khóa (với dòng đang Khóa) | J20: - Vào được màn hình - Có nút Tạo mới và nút Xuất Excel - Mỗi dòng có đủ 3 nút: Xem, Sửa, Xóa - Cột Trạng thái có nút Khóa (với dòng đang Hoạt động) hoặc Mở khóa (với dòng đang Khóa) | K20: Passed
C21: TC-ROLE-03 | D21: Chặn vào màn hình khi không có quyền nào | E21: P0 | F21: Tài khoản C không được cấp cả hai quyền "Xem danh mục tiền tệ" và "Quản lý danh mục tiền tệ". | G21: 1. Đăng nhập bằng tài khoản C 2. Mở phân hệ Tài chính, tìm mục Danh mục tiền tệ 3. Dán thẳng đường dẫn của màn Danh mục tiền tệ vào thanh địa chỉ | H21: Tài khoản C (không có quyền nào của màn này) | I21: - Mục menu Danh mục tiền tệ KHÔNG hiện trong phân hệ Tài chính - Dán thẳng đường dẫn thì hệ thống chuyển sang trang báo không tìm thấy, KHÔNG hiện dữ liệu tiền tệ nào Không được để lộ dù chỉ một phần bảng dữ liệu rồi mới chuyển trang | J21: - Mục menu Danh mục tiền tệ KHÔNG hiện trong phân hệ Tài chính - Dán thẳng đường dẫn thì hệ thống chuyển sang trang báo không tìm thấy, KHÔNG hiện dữ liệu tiền tệ nào Không được để lộ dù chỉ một phần bảng dữ liệu rồi mới chuyển trang | K21: Passed
C22: TC-ROLE-04 | D22: Chặn Thêm mới khi bỏ qua giao diện | E22: P0 | F22: Có sẵn 2 tài khoản: tài khoản A chỉ được cấp quyền "Xem danh mục tiền tệ"; tài khoản B được cấp quyền "Quản lý danh mục tiền tệ". Danh mục đang có 11 tiền tệ, trong đó VNĐ và USD đang được dùng ở chứng từ khác, tiền tệ "TST" mới tạo chưa dùng ở đâu. Chuẩn bị công cụ kiểm thử API và mã đăng nhập của tài khoản A. | G22: 1. Đăng nhập bằng tài khoản A, lấy mã đăng nhập 2. Dùng công cụ kiểm thử API gọi thẳng chức năng Thêm tiền tệ, bỏ qua giao diện 3. Mở lại màn Danh mục tiền tệ kiểm tra | H22: Mã tiền tệ: ZZZ; Tên tiền tệ: Tiền thử; Tỷ giá: 1,00 | I22: - Hệ thống từ chối, báo không có quyền - Danh sách vẫn 11 tiền tệ, không xuất hiện ZZZ Đây là nhóm dành cho tester kỹ thuật; nếu bản ghi được tạo là lỗ hổng phân quyền nghiêm trọng | J22: - Hệ thống từ chối, báo không có quyền - Danh sách vẫn 11 tiền tệ, không xuất hiện ZZZ Đây là nhóm dành cho tester kỹ thuật; nếu bản ghi được tạo là lỗ hổng phân quyền nghiêm trọng | K22: Passed
C23: TC-ROLE-05 | D23: Chặn Sửa khi bỏ qua giao diện | E23: P0 | F23: Có sẵn 2 tài khoản: tài khoản A chỉ được cấp quyền "Xem danh mục tiền tệ"; tài khoản B được cấp quyền "Quản lý danh mục tiền tệ". Danh mục đang có 11 tiền tệ, trong đó VNĐ và USD đang được dùng ở chứng từ khác, tiền tệ "TST" mới tạo chưa dùng ở đâu. | G23: 1. Đăng nhập bằng tài khoản A 2. Dùng công cụ kiểm thử API gọi thẳng chức năng Sửa tiền tệ USD, bỏ qua giao diện 3. Mở lại màn Danh mục tiền tệ, xem dòng USD | H23: Sửa Tên tiền tệ USD thành "Bị sửa trộm" | I23: - Hệ thống từ chối, báo không có quyền - Dòng USD giữ nguyên tên cũ và tỷ giá cũ | J23: - Hệ thống từ chối, báo không có quyền - Dòng USD giữ nguyên tên cũ và tỷ giá cũ | K23: Passed
C24: TC-ROLE-06 | D24: Chặn Xóa khi bỏ qua giao diện | E24: P0 | F24: Có sẵn 2 tài khoản: tài khoản A chỉ được cấp quyền "Xem danh mục tiền tệ"; tài khoản B được cấp quyền "Quản lý danh mục tiền tệ". Danh mục đang có 11 tiền tệ, trong đó VNĐ và USD đang được dùng ở chứng từ khác, tiền tệ "TST" mới tạo chưa dùng ở đâu. | G24: 1. Đăng nhập bằng tài khoản A 2. Dùng công cụ kiểm thử API gọi thẳng chức năng Xóa tiền tệ "TST", bỏ qua giao diện 3. Mở lại màn Danh mục tiền tệ | H24: Tiền tệ TST (chưa dùng ở đâu nên về nghiệp vụ là xóa được) | I24: - Hệ thống từ chối, báo không có quyền - Tiền tệ TST vẫn còn trong danh sách Bản ghi "xóa được" là phép thử nặng nhất: nếu quyền hở thì dữ liệu mất thật | J24: - Hệ thống từ chối, báo không có quyền - Tiền tệ TST vẫn còn trong danh sách Bản ghi "xóa được" là phép thử nặng nhất: nếu quyền hở thì dữ liệu mất thật | K24: Passed
C25: TC-ROLE-07 | D25: Chặn Khóa / Mở khóa khi bỏ qua giao diện | E25: P1 | F25: Có sẵn 2 tài khoản: tài khoản A chỉ được cấp quyền "Xem danh mục tiền tệ"; tài khoản B được cấp quyền "Quản lý danh mục tiền tệ". Danh mục đang có 11 tiền tệ, trong đó VNĐ và USD đang được dùng ở chứng từ khác, tiền tệ "TST" mới tạo chưa dùng ở đâu. | G25: 1. Đăng nhập bằng tài khoản A 2. Dùng công cụ kiểm thử API gọi thẳng chức năng Khóa tiền tệ USD, bỏ qua giao diện 3. Mở lại màn Danh mục tiền tệ | H25: Tiền tệ USD đang ở trạng thái Hoạt động | I25: - Hệ thống từ chối, báo không có quyền - USD vẫn ở trạng thái Hoạt động | J25: - Hệ thống từ chối, báo không có quyền - USD vẫn ở trạng thái Hoạt động | K25: Passed
C26: TC-ROLE-08 | D26: Người có quyền Quản lý làm được trọn vòng đời | E26: P1 | F26: Có sẵn 2 tài khoản: tài khoản A chỉ được cấp quyền "Xem danh mục tiền tệ"; tài khoản B được cấp quyền "Quản lý danh mục tiền tệ". Danh mục đang có 11 tiền tệ, trong đó VNĐ và USD đang được dùng ở chứng từ khác, tiền tệ "TST" mới tạo chưa dùng ở đâu. | G26: 1. Đăng nhập bằng tài khoản B 2. Tạo mới 1 tiền tệ 3. Sửa tiền tệ vừa tạo 4. Khóa rồi Mở khóa tiền tệ đó 5. Xóa tiền tệ đó | H26: Mã: TC1; Tên: Tiền kiểm thử; Tỷ giá: 1.000,00 | I26: - Cả 5 thao tác đều thực hiện được, mỗi thao tác có thông báo thành công tương ứng - Sau bước 5, tiền tệ TC1 không còn trong danh sách | J26: - Cả 5 thao tác đều thực hiện được, mỗi thao tác có thông báo thành công tương ứng - Sau bước 5, tiền tệ TC1 không còn trong danh sách | K26: Passed
C27: I. HIỂN THỊ TRANG & TRUY CẬP
A28: Danh mục tiền tệ | B28: HIỂN THỊ TRANG & TRUY CẬP | C28: TC_01.001 | D28: Mở màn hình lần đầu | E28: P0 | F28: Danh mục có 11 tiền tệ, trong đó 9 tiền tệ Hoạt động và 2 tiền tệ đang Khóa; có ít nhất 1 tiền tệ đã nhập Tên gọi khác (USD- Đô la Mỹ) và 1 tiền tệ bỏ trống Tên gọi khác. | G28: 1. Vào phân hệ Tài chính → Danh mục → Danh mục tiền tệ 2. Quan sát toàn màn hình | H28: — | I28: - Tiêu đề trang và tiêu đề bảng đều là "Danh mục tiền tệ" - Khối lọc phía trên có tiêu đề "Bộ lọc danh mục tiền tệ", mặc định ở dạng thu gọn (chỉ hiện ô tìm nhanh) - Bảng hiển thị đủ 7 cột theo đúng thứ tự: STT, Mã tiền tệ, Tên tiền tệ, Tỷ giá (VNĐ), Cập nhật, Trạng thái, Hành động - Dưới bảng có nút Tạo mới và nút Xuất Excel | J28: - Tiêu đề trang và tiêu đề bảng đều là "Danh mục tiền tệ" - Khối lọc phía trên có tiêu đề "Bộ lọc danh mục tiền tệ", mặc định ở dạng thu gọn (chỉ hiện ô tìm nhanh) - Bảng hiển thị đủ 7 cột theo đúng thứ tự: STT, Mã tiền tệ, Tên tiền tệ, Tỷ giá (VNĐ), Cập nhật, Trạng thái, Hành động - Dưới bảng có nút Tạo mới và nút Xuất Excel | K28: Passed
C29: TC_01.002 | D29: Kiểm tra hiển thị danh sách tiền tệ | E29: P0 | F29: Có 11 tiền tệ theo data test | G29: 1. Đăng nhập bằng tài khoản có quyền quản lý danh mục tiền tệ 2. Vào tài chính- > Danh mục- > Danh mục tiền tệ 3. Quan sát danh sách | H29: - | I29: - Hiển thị đủ 11 tiền tệ - Hiển thị cả tên Hoạt động và Khóa - Các cột hiển thị đúng thứ tự: STT, Mã tiền tệ, Tỷ giá (VNĐ), Cập nhật, Trạng thái, Hành động | J29: - Hiển thị đủ 11 tiền tệ - Hiển thị cả tên Hoạt động và Khóa - Các cột hiển thị đúng thứ tự: STT, Mã tiền tệ, Tỷ giá (VNĐ), Cập nhật, Trạng thái, Hành động | K29: Passed
C30: TC_01.003 | D30: Cột Tên tiền tệ hiện dòng phụ Tên gọi khác | E30: P1 | F30: USD có Tên gọi khác = Đô la mỹ; TST không có tên gọi khác | G30: 1. Mở màn hình 2. Nhìn dòng USD 3. Nhìn dòng TST không có tên gọi khác | H30: — | I30: - Dòng USD hiện tên tiền tệ ở dòng trên, dòng dưới hiện "Tên gọi khác: Đô la Mỹ" - TST chỉ hiển thị Tên tiền tệ, không hiển thị dòng Tện gọi khác trống | J30: - Dòng USD hiện tên tiền tệ ở dòng trên, dòng dưới hiện "Tên gọi khác: Đô la Mỹ" - TST chỉ hiển thị Tên tiền tệ, không hiển thị dòng Tện gọi khác trống | K30: Passed
C31: TC_01.004 | D31: Định dạng số của cột Tỷ giá (VNĐ) | E31: P0 | F31: Danh mục có các tỷ giá khác nhau | G31: 1. Mở Danh mục tiền tệ. 2. Kiểm tra cột Tỷ giá (VNĐ | H31: — | I31: - Tỷ giá hiển thị dạng 26.520,00 — dấu chấm ngăn hàng nghìn, dấu phẩy ngăn phần thập phân, luôn có đúng 2 chữ số thập phân Không được hiện dạng 26520 hay 26,520.00 | J31: - Tỷ giá hiển thị dạng 26.520,00 — dấu chấm ngăn hàng nghìn, dấu phẩy ngăn phần thập phân, luôn có đúng 2 chữ số thập phân Không được hiện dạng 26520 hay 26,520.00 | K31: Passed
C32: TC_01.005 | D32: Cột Trạng thái hiển thị đúng nhãn | E32: P0 | F32: Danh mục có 11 tiền tệ, trong đó 9 tiền tệ Hoạt động và 2 tiền tệ đang Khóa; có ít nhất 1 tiền tệ đã nhập Tên gọi khác (USD- Đô la Mỹ) và 1 tiền tệ bỏ trống Tên gọi khác. | G32: 1. Mở màn hình 2. Đối chiếu cột Trạng thái | H32: — | I32: Tỷ giá hiển thị theo định dạng Việt Nam. Ví dụ: 26.520,00. Có dấu chấm ngăn cách hàng nghìn và dấu phẩy ngăn phần thập phân, luôn có 2 chữ số thập phân | J32: Tỷ giá hiển thị theo định dạng Việt Nam. Ví dụ: 26.520,00. Có dấu chấm ngăn cách hàng nghìn và dấu phẩy ngăn phần thập phân, luôn có 2 chữ số thập phân | K32: Passed
C33: TC_01.006 | D33: Vị trí nút Khóa / Mở khóa | E33: P1 | F33: Danh mục có 11 tiền tệ, trong đó 9 tiền tệ Hoạt động và 2 tiền tệ đang Khóa; có ít nhất 1 tiền tệ đã nhập Tên gọi khác (USD- Đô la Mỹ) và 1 tiền tệ bỏ trống Tên gọi khác. | G33: 1. Mở màn hình 2. Nhìn cột Trạng thái và cột Hành động | H33: — | I33: - Nút Khóa (hình ổ khóa đóng) hoặc Mở khóa (hình ổ khóa mở) nằm ngay bên phải nhãn trạng thái, TRONG cột Trạng thái - Cột Hành động chỉ có 3 nút: Xem, Sửa, Xóa | J33: - Nút Khóa (hình ổ khóa đóng) hoặc Mở khóa (hình ổ khóa mở) nằm ngay bên phải nhãn trạng thái, TRONG cột Trạng thái - Cột Hành động chỉ có 3 nút: Xem, Sửa, Xóa | K33: Passed
C34: TC_01.007 | D34: Cột Cập nhật khi chưa có ngày cập nhật | E34: P2 | F34: Danh mục có 11 tiền tệ, trong đó 9 tiền tệ Hoạt động và 2 tiền tệ đang Khóa; có ít nhất 1 tiền tệ đã nhập Tên gọi khác (USD- Đô la Mỹ) và 1 tiền tệ bỏ trống Tên gọi khác. | G34: 1. Mở màn hình 2. Nhìn cột Cập nhật của mọi dòng | H34: — | I34: - Dòng có ngày cập nhật hiện đúng ngày giờ - Dòng chưa có ngày cập nhật hiện dấu gạch ngang, không để ô trắng trơn | J34: - Dòng có ngày cập nhật hiện đúng ngày giờ - Dòng chưa có ngày cập nhật hiện dấu gạch ngang, không để ô trắng trơn | K34: Passed
C35: TC_01.008 | D35: Bảng trống khi bộ lọc không khớp gì | E35: P1 | F35: Danh mục có 11 tiền tệ, trong đó 9 tiền tệ Hoạt động và 2 tiền tệ đang Khóa; có ít nhất 1 tiền tệ đã nhập Tên gọi khác (USD- Đô la Mỹ) và 1 tiền tệ bỏ trống Tên gọi khác. | G35: 1. Gõ vào ô tìm nhanh chuỗi "khongtontai123" 2. Bấm Tìm kiếm | H35: khongtontai123 | I35: - Bảng hiện dòng chữ "Không có dữ liệu phù hợp bộ lọc." - Dòng Hiển thị dưới bảng cho tổng là 0 - Nút Tạo mới và Xuất Excel vẫn còn | J35: - Bảng hiện dòng chữ "Không có dữ liệu phù hợp bộ lọc." - Dòng Hiển thị dưới bảng cho tổng là 0 - Nút Tạo mới và Xuất Excel vẫn còn | K35: Passed
C36: TC_01.009 | D36: Vào màn hình khi danh mục rỗng | E36: P2 | F36: Môi trường kiểm thử riêng, danh mục tiền tệ không có bản ghi nào. | G36: 1. Mở màn Danh mục tiền tệ | H36: — | I36: - Màn hình mở bình thường, không báo lỗi - Bảng hiện thông báo không có dữ liệu, tổng là 0 | J36: - Màn hình mở bình thường, không báo lỗi - Bảng hiện thông báo không có dữ liệu, tổng là 0 | K36: Passed
C37: II. BỘ LỌC & TÌM KIẾM
A38: Danh mục tiền tệ | B38: BỘ LỌC & TÌM KIẾM | C38: TC_02.001 | D38: Tìm nhanh theo Mã tiền tệ | E38: P0 | F38: Có USD trong danh sách | G38: 1. Gõ "USD" vào ô tìm nhanh 2. Bấm Tìm kiếm | H38: USD | I38: - Kết quả chỉ còn dòng có mã USD - Tổng dưới bảng đổi theo số dòng khớp | J38: - Kết quả chỉ còn dòng có mã USD - Tổng dưới bảng đổi theo số dòng khớp | K38: Passed
C39: TC_02.002 | D39: Tìm nhanh theo Tên tiền tệ | E39: P0 | F39: Có tiền tệ "Đô la Mỹ" | G39: 1. Gõ "Đô la" vào ô tìm nhanh 2. Bấm Tìm kiếm | H39: Đô la | I39: - Hiển thị các tiền tệ có chuỗi Đô la trong Tên tiền tệ hoặc Tên gọi khác | J39: - Hiển thị các tiền tệ có chuỗi Đô la trong Tên tiền tệ hoặc Tên gọi khác | K39: Passed
C40: TC_02.003 | D40: Tìm nhanh theo Tên gọi khác | E40: P0 | F40: USD có tên gọi khác = Đô la Mỹ | G40: 1. Gõ đúng phần Tên gọi khác của một tiền tệ (ví dụ "Đô la Mỹ") 2. Bấm Tìm kiếm | H40: Đô la Mỹ | I40: - Hiên thị USD dù chuỗi tìm kiếm nằm ở Tên gọi khác | J40: - Hiên thị USD dù chuỗi tìm kiếm nằm ở Tên gọi khác | K40: Passed
...

Sheet 3. DM tài khoản
A1: MÔ TẢ TÍNH NĂNG (đọc trước khi xem testcase)
A2: 1. Mục đích tính năng | B2: Quản lý hệ thống tài khoản kế toán 3 bậc dùng chung cho toàn hệ thống (hạch toán chứng từ, sổ sách, báo cáo tài chính, theo dõi công nợ). Màn hình nằm ở phân hệ Tài chính → nhóm menu Danh mục → Danh mục tài khoản. Đây là màn được chuyển từ hệ thống cũ sang, hai cổng dùng CHUNG một danh mục tài khoản.
A3: 2. Đối tượng được tính / hiển thị | B3: - Toàn bộ tài khoản trong danh mục, KHÔNG phân theo công ty / phòng ban — ai có quyền vào màn thì thấy đủ như nhau. - Hiển thị cả tài khoản Hoạt động và tài khoản đang Khóa. - Mỗi dòng gồm 11 cột: STT, Cấp 1, Cấp 2, Cấp 3, Tên tài khoản, Loại tài khoản, Theo dõi công nợ, Ngày tạo, Cập nhật, Trạng thái, Hành động. - Số tài khoản được đặt vào đúng cột Cấp 1 / Cấp 2 / Cấp 3 theo bậc của nó, ba cột còn lại để trống — nhờ vậy nhìn vào bảng là thấy ngay cây tài khoản thụt lề theo bậc. - Cột Theo dõi công nợ chỉ hiện dấu đánh dấu ở những tài khoản có bật, tài khoản không bật thì để trống.
A4: 3. Đối tượng bị ẩn / không tính | B4: - Không có tài khoản nào bị ẩn khỏi màn này. - Tài khoản đang Khóa VẪN hiện ở đây nhưng KHÔNG còn được chọn khi hạch toán chứng từ mới. - Trong danh sách chọn Tài khoản mẹ ở màn thêm/sửa: chỉ hiện các tài khoản đúng bậc liền trên bậc đang chọn (bậc 2 chỉ chọn được mẹ bậc 1, bậc 3 chỉ chọn được mẹ bậc 2).
A5: 4. Bộ lọc thời gian áp dụng cho | B5: Không áp dụng. Màn hình không có ô lọc theo khoảng thời gian. Hai cột Ngày tạo và Cập nhật chỉ để xem, không phải điều kiện lọc.
A6: 5. Cấu trúc dữ liệu / cây phân cấp | B6: Cây 3 bậc, gắn kết theo SỐ tài khoản chứ không theo tên: - Bậc 1: số tài khoản 3 chữ số, KHÔNG có tài khoản mẹ. Ví dụ 131. - Bậc 2: có tài khoản mẹ là một tài khoản bậc 1. Ví dụ 1311 (mẹ là 131). - Bậc 3: có tài khoản mẹ là một tài khoản bậc2. Ví dụ 13111 (mẹ là 1311). Ba quy tắc bắt buộc của cây: a) Tài khoản mẹ phải đúng bậc liền trên. b) Số tài khoản con phải BẮT ĐẦU BẰNG số tài khoản mẹ. c) Tài khoản đang có tài khoản con thì KHÔNG được đổi Bậc và KHÔNG được đổi Số tài khoản.
A7: 6. Quy tắc cộng dồn / deduplicate | B7: Không cộng dồn. Mỗi tài khoản là một dòng độc lập. Chống trùng: Số tài khoản là duy nhất trong toàn danh mục; trùng sẽ báo "Số tài khoản đã tồn tại". Tên tài khoản KHÔNG bắt buộc duy nhất — được phép trùng.
A8: 7. Phân quyền cấp | B8: Hai quyền dành riêng cho màn này: - "Xem danh mục tài khoản": vào màn hình, xem danh sách, mở xem chi tiết, xem lịch sử chỉnh sửa, in danh sách, xuất Excel. - "Quản lý danh mục tài khoản": thêm mới, sửa, khóa, mở khóa, xóa, nhập từ Excel. Không có quyền nào trong hai quyền trên thì không vào được màn hình. Danh mục KHÔNG phân quyền theo công ty / phòng ban / bộ phận. Ngoài quyền, còn một ràng buộc riêng: các thao tác Khóa, Mở khóa và Xóa chỉ dành cho CHÍNH NGƯỜI ĐÃ TẠO tài khoản đó. Người khác dù có quyền Quản lý cũng không thao tác được.
A9: 8. Cách tính các ô thống kê | B9: - Dòng "Hiển thị a- b / N" dưới bảng: a là dòng đầu của trang đang xem, b là dòng cuối, N là tổng số tài khoản khớp bộ lọc hiện tại. - Cột STT đánh theo trang: trang 2 với cỡ trang 10 thì bắt đầu từ 11. - Bản in danh sách lấy đúng tập dữ liệu đang lọc, không phải toàn bộ danh mục. - Bảng nhập từ Excel: số dòng hợp lệ và số dòng lỗi được đếm riêng.
A10: 9. Ghi chú đọc bảng | B10: - Số tài khoản chỉ được nhập CHỮ SỐ, từ 3 đến 15 chữ số. Chữ cái, dấu chấm, dấu gạch đều bị chặn. - Cột Cấp 1 / Cấp 2 / Cấp 3 KHÔNG phải ba số khác nhau — chỉ là một số tài khoản được đặt vào đúng cột theo bậc. Đọc nhầm thành ba giá trị là sai. - Nút Khóa / Mở khóa nằm NGAY TRONG cột Trạng thái, không nằm ở cột Hành động. - Tài khoản đang ở trạng thái Khóa thì nút Sửa bị vô hiệu; muốn sửa phải Mở khóa trước. - Người không phải người tạo sẽ thấy nút Khóa / Mở khóa / Xóa bị mờ, dù có quyền Quản lý. Đây là thiết kế, không phải lỗi. - Bộ lọc được hệ thống ghi nhớ trong 10 phút. Kiểm thử bộ lọc nên bấm Làm mới trước mỗi kịch bản. - Thêm mới và Sửa mở ra TRANG RIÊNG, không phải cửa sổ nhỏ như các danh mục khác. - Mọi thay đổi đều xem lại được qua nút Lịch sử chỉnh sửa trên từng dòng.
A11: Testcase _ Danh mục tài khoản- Cập nhật ngày 14/08/2026 | F11: TEST SUMMARY | I11: Số TH DNS kiểm thử đạt (P): | K11: =COUNTIF(K18:M997,"Passed") | M11: Số trường hợp TP kiểm thử đạt (P): | P11: =COUNTIF(O18:Q200,"Passed")
I12: Số TH DNS kiểm thử không đạt (F) | K12: =COUNTIF(K18:M997,"Failed") | M12: Số trường hợp TP kiểm thử không đạt (F) | P12: =COUNTIF(O19:Q201,"Fail")
I13: Số TH DNS kiểm thử đang xem xét (PE) | K13: =COUNTIF(K18:M997,"Pending") | M13: Số trường hợp TP kiểm thử đang xem xét (PE) | P13: =COUNTIF(O20:Q202,"Pending")
I14: Số TH DNS kiểm thử chưa thực hiện | K14: =COUNTIF(K18:K997,"Not Executed") | M14: Số trường hợp TP kiểm thử chưa thực hiện | P14: =K16-P15
I15: Tổng số TH DNS đã kiểm thử | K15: =sum(K11:K14) | M15: Tổng số trường hợp TP kiểm thử | P15: =sum(P11:Q13)
I16: Tổng số testcase | K16: =COUNTIF(I18:I1017,"*")
A17: Module | B17: Nhóm chức năng | C17: TC ID | D17: Chức năng | E17: Priority | F17: Tiền điều kiện | G17: Bước thực hiện | H17: Test Data | I17: Expected Result (chi tiết) | J17: KQ thực tế | K17: DNS check lần 1 | L17: DNS check lần 2 | M17: DNS check lần 3 | N17: Ghi chú | O17: TP check lần 1 | P17: TP check lần 2 | Q17: TP check lần 3
C18: Phân quyền & truy cập
A19: Danh mục tài khoản | B19: Phân quyền & truy cập | C19: TC-ROLE-01 | D19: Vào màn hình khi chỉ có quyền Xem | E19: P0 | F19: Đăng nhập User A (chỉ có quyền Xem). | G19: 1. Đăng nhập bằng tài khoản A 2. Vào phân hệ Tài chính → Danh mục → Danh mục tài khoản | H19: Tài khoản A | I19: - Vào được màn hình, bảng hiển thị dữ liệu - KHÔNG có nút Tạo mới, KHÔNG có nút Import Excel - Trên mỗi dòng chỉ còn nút Lịch sử chỉnh sửa; KHÔNG có nút Sửa, nút Xóa - Cột Trạng thái không có nút Khóa / Mở khóa - Vẫn có nút In danh sách và nút Xuất Excel | K19: Passed
C20: TC-ROLE-02 | D20: Vào màn hình khi có quyền Quản lý | E20: P0 | F20: Đăng nhập User B (quyền Quản lý). | G20: 1. Đăng nhập bằng tài khoản B 2. Vào Danh mục tài khoản | H20: Tài khoản B | I20: - Có đủ 4 nút dưới bảng: Tạo mới, In danh sách, Xuất Excel, Import Excel - Mỗi dòng có đủ 3 nút: Sửa, Lịch sử chỉnh sửa, Xóa - Cột Trạng thái có nút Khóa hoặc Mở khóa | K20: Passed
C21: TC-ROLE-03 | D21: Chặn vào màn hình khi không có quyền nào | E21: P0 | F21: Đăng nhập User D (không có quyền). | G21: 1. Đăng nhập bằng tài khoản D 2. Tìm mục Danh mục tài khoản trong phân hệ Tài chính 3. Dán thẳng đường dẫn màn hình vào thanh địa chỉ | H21: Tài khoản D | I21: - Mục menu KHÔNG hiện - Dán thẳng đường dẫn thì hệ thống chuyển sang trang báo không tìm thấy, không lộ dữ liệu | K21: Passed
C22: TC-ROLE-04 | D22: Chặn vào trang Thêm mới khi chỉ có quyền Xem | E22: P0 | F22: Đăng nhập User A. | G22: 1. Đăng nhập bằng tài khoản A 2. Dán thẳng đường dẫn trang Thêm tài khoản vào thanh địa chỉ | H22: Tài khoản A | I22: - Hệ thống không cho vào trang thêm mới, chuyển sang trang báo không tìm thấy hoặc quay về danh sách kèm thông báo không có quyền | K22: Passed
C23: TC-ROLE-05 | D23: Chặn Thêm mới khi bỏ qua giao diện | E23: P0 | F23: Đăng nhập User A. | G23: 1. Đăng nhập bằng tài khoản A, lấy mã đăng nhập 2. Dùng công cụ kiểm thử API gọi thẳng chức năng Thêm tài khoản, bỏ qua giao diện 3. Mở lại màn hình kiểm tra | H23: Số tài khoản: 998; Tên: Tài khoản thử; Bậc 1 | I23: - Hệ thống từ chối, báo không có quyền - Không xuất hiện tài khoản 998 | K23: Passed
C24: TC-ROLE-06 | D24: Chặn Sửa khi bỏ qua giao diện | E24: P0 | F24: Đăng nhập User A. | G24: 1. Đăng nhập bằng tài khoản A 2. Dùng công cụ kiểm thử API gọi thẳng chức năng Sửa tài khoản 999 3. Mở lại màn hình | H24: Đổi tên thành "Bị sửa trộm" | I24: - Hệ thống từ chối, báo không có quyền - Tên cũ giữ nguyên | K24: Passed
C25: TC-ROLE-07 | D25: Chặn Xóa khi bỏ qua giao diện | E25: P0 | F25: Đăng nhập User A. | G25: 1. Đăng nhập bằng tài khoản A 2. Dùng công cụ kiểm thử API gọi thẳng chức năng Xóa tài khoản 999 3. Mở lại màn hình | H25: Tài khoản 999 (về nghiệp vụ là xóa được) | I25: - Hệ thống từ chối, báo không có quyền - Tài khoản 999 vẫn còn | K25: Passed
C26: TC-ROLE-08 | D26: Chặn Xóa của người có quyền nhưng không phải người tạo | E26: P0 | F26: Đăng nhập User C (không tạo tài khoản 999). | G26: 1. Đăng nhập bằng tài khoản C (có quyền Quản lý, KHÔNG phải người tạo 999) 2. Dùng công cụ kiểm thử API gọi thẳng chức năng Xóa tài khoản 999 3. Mở lại màn hình | H26: Tài khoản C xóa tài khoản 999 của người khác | I26: - Hệ thống từ chối - Tài khoản 999 vẫn còn Đây là ràng buộc riêng của màn này: chỉ chính người tạo mới được xóa | K26: Passed
C27: TC-ROLE-09 | D27: Chặn Khóa của người có quyền nhưng không phải người tạo | E27: P0 | F27: Đăng nhập User C (không tạo tài khoản 999). | G27: 1. Đăng nhập bằng tài khoản C 2. Mở màn hình, rê chuột vào nút Khóa của dòng 999 3. Dùng công cụ kiểm thử API gọi thẳng chức năng Khóa tài khoản 999 | H27: Tài khoản C | I27: - Trên giao diện nút Khóa bị mờ - Gọi thẳng cũng bị từ chối, trạng thái tài khoản 999 không đổi | K27: Passed
C28: TC-ROLE-10 | D28: Chặn Import Excel khi bỏ qua giao diện | E28: P1 | F28: Đăng nhập User A. | G28: 1. Đăng nhập bằng tài khoản A 2. Dùng công cụ kiểm thử API gọi thẳng chức năng Nhập tài khoản từ Excel 3. Mở lại màn hình | H28: File Excel 3 dòng hợp lệ | I28: - Hệ thống từ chối, báo không có quyền - Danh sách không tăng thêm dòng nào | K28: Passed
C29: TC-ROLE-11 | D29: Người chỉ có quyền Xem vẫn in và xuất Excel được | E29: P1 | F29: Đăng nhập User A. | G29: 1. Đăng nhập bằng tài khoản A 2. Bấm In danh sách 3. Bấm Xuất Excel | H29: Tài khoản A | I29: - Cả hai chức năng đều dùng được bình thường | K29: Passed
C30: TC-ROLE-12 | D30: Kiểm tra mở chức năng Cấu hình cột hiển thị | E30: P1 | F30: Người dùng có quyền truy cập màn Danh mục tài khoản | G30: 1. Vào màn Danh mục tài khoản. 2. Bấm Cấu hình cột hiển thị. | H30: - | I30: Popup Cấu hình cột hiển thị được mở. Hiển thị đầy đủ các cột được phép cấu hình theo nghiệp vụ. | K30: Passed
C31: TC-ROLE-13 | D31: Kiểm tra trạng thái mặc định của các cột | F31: Đã mở popup Cấu hình cột hiển thị | G31: 1. Quan sát danh sách các cột trong popup. | H31: - | I31: Các cột mặc định được chọn đúng theo cấu hình mặc định của màn Danh mục tài khoản. Các cột không mặc định được bỏ chọn. | K31: Passed
C32: I. HIỂN THỊ TRANG & TRUY CẬP
A33: Danh mục tài khoản | B33: HIỂN THỊ TRANG & TRUY CẬP | C33: TC_01.001 | D33: Mở màn hình lần đầu | E33: P0 | F33: Đăng nhập TK "Quản lý". Đang ở màn hình khác. | G33: 1. Vào phân hệ Tài chính → Danh mục → Danh mục tài khoản 2. Quan sát toàn màn hình | I33: - Tiêu đề trang và tiêu đề bảng đều là "Danh mục tài khoản" - Khối lọc có tiêu đề "Bộ lọc danh mục tài khoản", mặc định thu gọn - Bảng có đủ 11 cột đúng thứ tự: STT, Cấp 1, Cấp 2, Cấp 3, Tên tài khoản, Loại tài khoản, Theo dõi công nợ, Ngày tạo, Cập nhật, Trạng thái, Hành động - Dưới bảng có 4 nút: Tạo mới, In danh sách, Xuất Excel, Import Excel | J33: - Tiêu đề trang và tiêu đề bảng đều là "Danh mục tài khoản" - Khối lọc có tiêu đề "Bộ lọc danh mục tài khoản", mặc định thu gọn - Bảng có đủ 11 cột đúng thứ tự: STT, Cấp 1, Cấp 2, Cấp 3, Tên tài khoản, Loại tài khoản, Theo dõi công nợ, Ngày tạo, Cập nhật, Trạng thái, Hành động - Dưới bảng có 4 nút: Tạo mới, In danh sách, Xuất Excel, Import Excel | K33: Passed
C34: TC_01.002 | D34: Số tài khoản nằm đúng cột theo bậc | E34: P0 | F34: Đăng nhập TK "Quản lý". Đang ở màn Danh mục. | G34: 1. Mở màn hình 2. Tìm ba dòng 131, 1311, 13111 và nhìn 3 cột Cấp | I34: - Dòng 131 chỉ điền cột Cấp 1, hai cột Cấp 2 và Cấp 3 để trống - Dòng 1311 chỉ điền cột Cấp 2 - Dòng 13111 chỉ điền cột Cấp 3 Nhìn ngang là thấy cây thụt lề theo bậc; số chỉ xuất hiện MỘT lần trên mỗi dòng | J34: - Dòng 131 chỉ điền cột Cấp 1, hai cột Cấp 2 và Cấp 3 để trống - Dòng 1311 chỉ điền cột Cấp 2 - Dòng 13111 chỉ điền cột Cấp 3 Nhìn ngang là thấy cây thụt lề theo bậc; số chỉ xuất hiện MỘT lần trên mỗi dòng | K34: Passed
C35: TC_01.003 | D35: Cột Theo dõi công nợ | E35: P1 | F35: Đăng nhập TK "Quản lý". Đang ở màn Danh mục. | G35: 1. Mở màn hình 2. So sánh dòng có bật và dòng không bật theo dõi công nợ | I35: - Dòng có bật hiện dấu đánh dấu, rê chuột hiện chú thích "Có theo dõi công nợ" - Dòng không bật để trống, không hiện dấu gạch hay chữ "Không" | J35: - Dòng có bật hiện dấu đánh dấu, rê chuột hiện chú thích "Có theo dõi công nợ" - Dòng không bật để trống, không hiện dấu gạch hay chữ "Không" | K35: Passed
